Workbook

Sheet CompetitorDetails
A1: name | B1: address | C1: location_name
A2: Flamboyante | B2: World Trade Centre (Cuffe Parade, Colaba), Mumbai 400005, Mahārāshtra | C2: Colaba
A3: Village | B3: World Trade Centre, Tower 5 (Cuffe Parade), Mumbai 400005, Mahārāshtra | C3: Colaba
A4: Nature's Basket | B4: World Trade Centre Arcade (Cuffe Parade), Mumbai 400005, Mahārāshtra | C4: Colaba
A5: Baskin-Robbins | B5: World Trade Center Shopping Arcade, Mumbai 400005, Mahārāshtra | C5: Colaba
A6: UAE Consulate General | B6: United Arab Emirates Consulate General in Mumbai, India (No.7, Jolly Maker, Apartment No. 1, Cuffe Parade, ), Mumbai 400005, Mahārāshtra | C6: Colaba
A7: Vivek Vaswani | B7: 141 142 Dalamal Park, Cuffe Parade Bombay, 400005 | C7: Colaba
A8: Vijay Medico Pharma | B8: 12/C Usha Sadan, S B S Road, Mumbai 400005, Mahārāshtra | C8: Colaba
A9: Mulla Auditorium | B9: Colaba, Mumbai, Mahārāshtra | C9: Colaba
A10: Manoj | C10: Colaba
A11: WTC Pasta | B11: Cuffe Parade | C11: Colaba
A12: Colaba Woods | B12: Off Prakash Pathe Road, Mumbai 400 005, Mahārāshtra | C12: Colaba
A13: Colabawoods Basketball Court | B13: Cuffe Parade 50, Mumbai 400005, Mahārāshtra | C13: Colaba
A14: Cuffe Parade | B14: Cuffe Parade,, Mumbai 400 005., Mahārāshtra | C14: Colaba
A15: King Plaza | B15: Maker Arcade (Cuffe Parade), Mumbai 400005, Mahārāshtra | C15: Colaba
A16: Mr. Chow | B16: Shahid Bhagatsingh Marg, Colaba, Mumbai, Mahārāshtra | C16: Colaba
A17: Natural's Ice Cream | B17: Mumbai, Mahārāshtra | C17: Colaba
A18: Idris Bhai Roll | C18: Colaba
A19: Maker Arcade | B19: Maker Towers (Cuffe Parade), Mumbai 400005, Mahārāshtra | C19: Colaba
A20: Café Coffee Day | B20: Maker Arcade (Cuffe Parade), Mumbai 400005, Mahārāshtra | C20: Colaba
A21: Santoor | B21: 9/10 Maker Arcade, Mumbai 400 005, Mahārāshtra | C21: Colaba
A22: B. D. Somani International School | B22: Cuffe Parade (G. D. Somani marg), Mumbai 400 005, Mahārāshtra | C22: Colaba
A23: Land's End Park | C23: Colaba
A24: Gym TajHotel | B24: www.tajhotels.com | C24: Colaba
A25: Santoor Pure Vegetarian | C25: Colaba
A26: Good Luck Motor Driving School | B26: 7, Hampton Court (125 Wodehouse Road, Volans), Mumbai 400005, Mahārāshtra | C26: Colaba
A27: Sunshine Snack Corner | C27: Colaba
A28: La Patisserie | B28: Vivanta by Taj President (90 Cuffe Parade), Mumbai 400005, Mahārāshtra | C28: Colaba
A29: Thai Pavilion | B29: Vivanta by Taj - President (90 Cuffe Parade), Mumbai 400005, Mahārāshtra | C29: Colaba
A30: Konkan Cafe | B30: Vivanta by Taj - President (90 Cuffe Parade), Mumbai 400005, Mahārāshtra | C30: Colaba
A31: Wink | B31: Vivanta by Taj - President (90 Cuffe Parade), Mumbai 400005, Mahārāshtra | C31: Colaba
A32: Konkan Cafe | B32: 90 Cuffe Parade, Mumbai 400005, Mahārāshtra | C32: Colaba
A33: Trattoria | B33: Vivanta by Taj - President (90 Cuffe Parade), Mumbai 400005, Mahārāshtra | C33: Colaba
A34: Pasta Ring | B34: Cuffe parade, Mumbai, Mahārāshtra | C34: Colaba
A35: Consulate General of the United Arab Emirates | B35: Maker Tower 'F' (Cuffe Parade), Mumbai 400005, Mahārāshtra | C35: Colaba
A36: Alliance Française | B36: G D Somani Marg (Cuffe Parade), Mumbai 400005, Mahārāshtra | C36: Colaba
A37: Olympia Coffee House | B37: 1 Shahid Bhagat Singh Road, Mumbai 400 039, Mahārāshtra | C37: Colaba
A38: Umame | B38: church gate, Mumbai, Mahārāshtra | C38: Fort
A39: Pronto | B39: Churchgate, Eros Cinema Building (Maharishi Karve Road), Mumbai 400020, Mahārāshtra | C39: Fort
... A72: Volga Paan Wala | B72: Near hornimon circle, Fort (D N Road, Hutatama Chowk), Mumbai, Mahārāshtra | C72: Fort
...

Sheet MumbaiLocationAnalysis
A1: location_name | B1: latitude | C1: longitude | D1: restaurant | E1: cafe | F1: bar | G1: bakery | H1: meal_takeaway | I1: shopping_mall | J1: clothing_store | K1: supermarket | L1: gym | M1: park | N1: library | O1: museum | P1: tourist_attraction | Q1: office | R1: bank | S1: hospital | T1: school | U1: university
A2: Colaba | B2: 18.913 | C2: 72.8172 | D2: 36 | E2: 36 | F2: 36 | G2: 36 | H2: 36 | I2: 36 | J2: 36 | K2: 36 | L2: 36 | M2: 36 | N2: 36 | O2: 36 | P2: 36 | Q2: 36 | R2: 36 | S2: 36 | T2: 36 | U2: 36
A3: Fort | B3: 18.9322 | C3: 72.8293 | D3: 50 | E3: 50 | F3: 50 | G3: 50 | H3: 50 | I3: 50 | J3: 50 | K3: 50 | L3: 50 | M3: 50 | N3: 50 | O3: 50 | P3: 50 | Q3: 50 | R3: 50 | S3: 50 | T3: 50 | U3: 50
A4: Churchgate | B4: 18.935 | C4: 72.8268 | D4: 50 | E4: 50 | F4: 50 | G4: 50 | H4: 50 | I4: 50 | J4: 50 | K4: 50 | L4: 50 | M4: 50 | N4: 50 | O4: 50 | P4: 50 | Q4: 50 | R4: 50 | S4: 50 | T4: 50 | U4: 50
A5: Marine Lines | B5: 18.946 | C5: 72.823 | D5: 9 | E5: 9 | F5: 9 | G5: 9 | H5: 9 | I5: 9 | J5: 9 | K5: 9 | L5: 9 | M5: 9 | N5: 9 | O5: 9 | P5: 9 | Q5: 9 | R5: 9 | S5: 9 | T5: 9 | U5: 9
A6: Dadar | B6: 19.0161 | C6: 72.8487 | D6: 22 | E6: 22 | F6: 22 | G6: 22 | H6: 22 | I6: 22 | J6: 22 | K6: 22 | L6: 22 | M6: 22 | N6: 22 | O6: 22 | P6: 22 | Q6: 22 | R6: 22 | S6: 22 | T6: 22 | U6: 22
A7: Lower Parel | B7: 18.9939 | C7: 72.8255 | D7: 50 | E7: 50 | F7: 50 | G7: 50 | H7: 50 | I7: 50 | J7: 50 | K7: 50 | L7: 50 | M7: 50 | N7: 50 | O7: 50 | P7: 50 | Q7: 50 | R7: 50 | S7: 50 | T7: 50 | U7: 50
A8: Bandra West | B8: 19.0596 | C8: 72.8295 | D8: 50 | E8: 50 | F8: 50 | G8: 50 | H8: 50 | I8: 50 | J8: 50 | K8: 50 | L8: 50 | M8: 50 | N8: 50 | O8: 50 | P8: 50 | Q8: 50 | R8: 50 | S8: 50 | T8: 50 | U8: 50
A9: Bandra Kurla Complex | B9: 19.0636 | C9: 72.8681 | D9: 29 | E9: 29 | F9: 29 | G9: 29 | H9: 29 | I9: 29 | J9: 29 | K9: 29 | L9: 29 | M9: 29 | N9: 29 | O9: 29 | P9: 29 | Q9: 29 | R9: 29 | S9: 29 | T9: 29 | U9: 29
A10: Andheri East | B10: 19.1173 | C10: 72.8508 | D10: 40 | E10: 40 | F10: 40 | G10: 40 | H10: 40 | I10: 40 | J10: 40 | K10: 40 | L10: 40 | M10: 40 | N10: 40 | O10: 40 | P10: 40 | Q10: 40 | R10: 40 | S10: 40 | T10: 40 | U10: 40
A11: Andheri West | B11: 19.1275 | C11: 72.812 | D11: 13 | E11: 13 | F11: 13 | G11: 13 | H11: 13 | I11: 13 | J11: 13 | K11: 13 | L11: 13 | M11: 13 | N11: 13 | O11: 13 | P11: 13 | Q11: 13 | R11: 13 | S11: 13 | T11: 13 | U11: 13
A12: Juhu | B12: 19.1026 | C12: 72.826 | D12: 50 | E12: 50 | F12: 50 | G12: 50 | H12: 50 | I12: 50 | J12: 50 | K12: 50 | L12: 50 | M12: 50 | N12: 50 | O12: 50 | P12: 50 | Q12: 50 | R12: 50 | S12: 50 | T12: 50 | U12: 50
A13: Powai | B13: 19.124 | C13: 72.9068 | D13: 33 | E13: 33 | F13: 33 | G13: 33 | H13: 33 | I13: 33 | J13: 33 | K13: 33 | L13: 33 | M13: 33 | N13: 33 | O13: 33 | P13: 33 | Q13: 33 | R13: 33 | S13: 33 | T13: 33 | U13: 33
... A22: Vikhroli | B22: 19.117 | C22: 72.918 | D22: 4 | E22: 4 | F22: 4 | G22: 4 | H22: 4 | I22: 4 | J22: 4 | K22: 4 | L22: 4 | M22: 4 | N22: 4 | O22: 4 | P22: 4 | Q22: 4 | R22: 4 | S22: 4 | T22: 4 | U22: 4

Sheet Assumptions
A1: Assumption | B1: Value | C1: Unit
A2: Average Spend per Customer | B2: 450 | C2: per visit
A3: Daily Customers per 1000 Foot Traffic | B3: 80 | C3: people
A4: Operating Days per Month | B4: 30 | C4: days
A5: Monthly Rent (Base) | B5: 90000 | C5: per month
A6: Staff Cost (Base) | B6: 80000 | C6: per month
A7: Utilities & Other Costs | B7: 30000 | C7: per month
A8: Marketing Budget | B8: 20000 | C8: per month
A9: Expected Profit Margin | B9: 0.25 | C9: % of revenue
A10: Initial Investment | B10: 2000000 | C10: one-time
A13: Rent Scenario | B13: 1
A15: Foot Traffic Scenario | B15: 1

Sheet Model
A1: Location | B1: Score | C1: Foot Traffic | D1: Cafe Count | E1: Est. Daily Customers | F1: Monthly Revenue | G1: Monthly Costs | H1: Monthly Profit | I1: ROI | J1: Recommendation | K1: Break-even Revenue | L1: Customers Needed | M1: Profitability Potential
A2: =INDEX(MumbaiLocationAnalysis[], ROW()-1, 1) -> Colaba | B2: =INDEX(MumbaiLocationAnalysis[], ROW()-1, MATCH("restaurant", MumbaiLocationAnalysis[#Headers], 0))*0.8 + INDEX(MumbaiLocationAnalysis[], ROW()-1, MATCH("shopping_mall", MumbaiLocationAnalysis[#Headers], 0))*0.7 + INDEX(MumbaiLocationAnalysis[], ROW()-1, MATCH("office", MumbaiLocationAnalysis[#Headers], 0))*0.6 + INDEX(MumbaiLocationAnalysis[], ROW()-1, MATCH("park", MumbaiLocationAnalysis[#Headers], 0))*0.5 + INDEX(MumbaiLocationAnalysis[], ROW()-1, MATCH("gym", MumbaiLocationAnalysis[#Headers], 0))*0.4 + INDEX(MumbaiLocationAnalysis[], ROW()-1, MATCH("tourist_attraction", MumbaiLocationAnalysis[#Headers], 0))*0.6 + INDEX(MumbaiLocationAnalysis[], ROW()-1, MATCH("bank", MumbaiLocationAnalysis[#Headers], 0))*0.3 + INDEX(MumbaiLocationAnalysis[], ROW()-1, MATCH("hospital", MumbaiLocationAnalysis[#Headers], 0))*0.3 + INDEX(MumbaiLocationAnalysis[], ROW()-1, MATCH("school", MumbaiLocationAnalysis[#Headers], 0))*0.3 - INDEX(MumbaiLocationAnalysis[], ROW()-1, MATCH("cafe", MumbaiLocationAnalysis[#Headers], 0))*0.8 -> 133.2 | C2: =INDEX(MumbaiLocationAnalysis[], ROW()-1, MATCH("restaurant", MumbaiLocationAnalysis[#Headers], 0)) + INDEX(MumbaiLocationAnalysis[], ROW()-1, MATCH("shopping_mall", MumbaiLocationAnalysis[#Headers], 0)) + INDEX(MumbaiLocationAnalysis[], ROW()-1, MATCH("office", MumbaiLocationAnalysis[#Headers], 0)) + INDEX(MumbaiLocationAnalysis[], ROW()-1, MATCH("park", MumbaiLocationAnalysis[#Headers], 0)) + INDEX(MumbaiLocationAnalysis[], ROW()-1, MATCH("tourist_attraction", MumbaiLocationAnalysis[#Headers], 0)) -> 180 | D2: =INDEX(MumbaiLocationAnalysis[], ROW()-1, MATCH("cafe", MumbaiLocationAnalysis[#Headers], 0)) -> 36 | E2: =(C2 * Assumptions!$B$3 / 1000) * Assumptions!$B$15 -> 14.4 | F2: =E2 * Assumptions!$B$2 * Assumptions!$B$4 -> 194400 | G2: =(Assumptions!$B$5 * Assumptions!$B$13) + Assumptions!$B$6 + Assumptions!$B$7 + Assumptions!$B$8 -> 220000 | H2: =F2 - G2 -> -25600 | I2: =H2 / Assumptions!$B$10 -> -0.0128 | J2: =IF(B2>150,"Strongly Recommended",IF(B2>120,"Worth Considering",IF(B2>100,"Low Potential","Strongly Discouraged"))) -> Worth Considering | K2: =G2 / Assumptions!$B$9 -> 880000 | L2: =K2 / (Assumptions!$B$2 * Assumptions!$B$4) -> 65.185185 | M2: =IF(H2 > 0, "Profitable", "Needs Improvement") -> Needs Improvement
A3: =INDEX(MumbaiLocationAnalysis[], ROW()-1, 1) -> Fort | B3: =INDEX(MumbaiLocationAnalysis[], ROW()-1, MATCH("restaurant", MumbaiLocationAnalysis[#Headers], 0))*0.8 + INDEX(MumbaiLocationAnalysis[], ROW()-1, MATCH("shopping_mall", MumbaiLocationAnalysis[#Headers], 0))*0.7 + INDEX(MumbaiLocationAnalysis[], ROW()-1, MATCH("office", MumbaiLocationAnalysis[#Headers], 0))*0.6 + INDEX(MumbaiLocationAnalysis[], ROW()-1, MATCH("park", MumbaiLocationAnalysis[#Headers], 0))*0.5 + INDEX(MumbaiLocationAnalysis[], ROW()-1, MATCH("gym", MumbaiLocationAnalysis[#Headers], 0))*0.4 + INDEX(MumbaiLocationAnalysis[], ROW()-1, MATCH("tourist_attraction", MumbaiLocationAnalysis[#Headers], 0))*0.6 + INDEX(MumbaiLocationAnalysis[], ROW()-1, MATCH("bank", MumbaiLocationAnalysis[#Headers], 0))*0.3 + INDEX(MumbaiLocationAnalysis[], ROW()-1, MATCH("hospital", MumbaiLocationAnalysis[#Headers], 0))*0.3 + INDEX(MumbaiLocationAnalysis[], ROW()-1, MATCH("school", MumbaiLocationAnalysis[#Headers], 0))*0.3 - INDEX(MumbaiLocationAnalysis[], ROW()-1, MATCH("cafe", MumbaiLocationAnalysis[#Headers], 0))*0.8 -> 185 | C3: =INDEX(MumbaiLocationAnalysis[], ROW()-1, MATCH("restaurant", MumbaiLocationAnalysis[#Headers], 0)) + INDEX(MumbaiLocationAnalysis[], ROW()-1, MATCH("shopping_mall", MumbaiLocationAnalysis[#Headers], 0)) + INDEX(MumbaiLocationAnalysis[], ROW()-1, MATCH("office", MumbaiLocationAnalysis[#Headers], 0)) + INDEX(MumbaiLocationAnalysis[], ROW()-1, MATCH("park", MumbaiLocationAnalysis[#Headers], 0)) + INDEX(MumbaiLocationAnalysis[], ROW()-1, MATCH("tourist_attraction", MumbaiLocationAnalysis[#Headers], 0)) -> 250 | D3: =INDEX(MumbaiLocationAnalysis[], ROW()-1, MATCH("cafe", MumbaiLocationAnalysis[#Headers], 0)) -> 50 | E3: =(C3 * Assumptions!$B$3 / 1000) * Assumptions!$B$15 -> 20 | F3: =E3 * Assumptions!$B$2 * Assumptions!$B$4 -> 270000 | G3: =(Assumptions!$B$5 * Assumptions!$B$13) + Assumptions!$B$6 + Assumptions!$B$7 + Assumptions!$B$8 -> 220000 | H3: =F3 - G3 -> 50000 | I3: =H3 / Assumptions!$B$10 -> 0.025 | J3: =IF(B3>150,"Strongly Recommended",IF(B3>120,"Worth Considering",IF(B3>100,"Low Potential","Strongly Discouraged"))) -> Strongly Recommended | K3: =G3 / Assumptions!$B$9 -> 880000 | L3: =K3 / (Assumptions!$B$2 * Assumptions!$B$4) -> 65.185185 | M3: =IF(H3 > 0, "Profitable", "Needs Improvement") -> Profitable
A4: =INDEX(MumbaiLocationAnalysis[], ROW()-1, 1) -> Churchgate | B4: =INDEX(MumbaiLocationAnalysis[], ROW()-1, MATCH("restaurant", MumbaiLocationAnalysis[#Headers], 0))*0.8 + INDEX(MumbaiLocationAnalysis[], ROW()-1, MATCH("shopping_mall", MumbaiLocationAnalysis[#Headers], 0))*0.7 + INDEX(MumbaiLocationAnalysis[], ROW()-1, MATCH("office", MumbaiLocationAnalysis[#Headers], 0))*0.6 + INDEX(MumbaiLocationAnalysis[], ROW()-1, MATCH("park", MumbaiLocationAnalysis[#Headers], 0))*0.5 + INDEX(MumbaiLocationAnalysis[], ROW()-1, MATCH("gym", MumbaiLocationAnalysis[#Headers], 0))*0.4 + INDEX(MumbaiLocationAnalysis[], ROW()-1, MATCH("tourist_attraction", MumbaiLocationAnalysis[#Headers], 0))*0.6 + INDEX(MumbaiLocationAnalysis[], ROW()-1, MATCH("bank", MumbaiLocationAnalysis[#Headers], 0))*0.3 + INDEX(MumbaiLocationAnalysis[], ROW()-1, MATCH("hospital", MumbaiLocationAnalysis[#Headers], 0))*0.3 + INDEX(MumbaiLocationAnalysis[], ROW()-1, MATCH("school", MumbaiLocationAnalysis[#Headers], 0))*0.3 - INDEX(MumbaiLocationAnalysis[], ROW()-1, MATCH("cafe", MumbaiLocationAnalysis[#Headers], 0))*0.8 -> 185 | C4: =INDEX(MumbaiLocationAnalysis[], ROW()-1, MATCH("restaurant", MumbaiLocationAnalysis[#Headers], 0)) + INDEX(MumbaiLocationAnalysis[], ROW()-1, MATCH("shopping_mall", MumbaiLocationAnalysis[#Headers], 0)) + INDEX(MumbaiLocationAnalysis[], ROW()-1, MATCH("office", MumbaiLocationAnalysis[#Headers], 0)) + INDEX(MumbaiLocationAnalysis[], ROW()-1, MATCH("park", MumbaiLocationAnalysis[#Headers], 0)) + INDEX(MumbaiLocationAnalysis[], ROW()-1, MATCH("tourist_attraction", MumbaiLocationAnalysis[#Headers], 0)) -> 250 | D4: =INDEX(MumbaiLocationAnalysis[], ROW()-1, MATCH("cafe", MumbaiLocationAnalysis[#Headers], 0)) -> 50 | E4: =(C4 * Assumptions!$B$3 / 1000) * Assumptions!$B$15 -> 20 | F4: =E4 * Assumptions!$B$2 * Assumptions!$B$4 -> 270000 | G4: =(Assumptions!$B$5 * Assumptions!$B$13) + Assumptions!$B$6 + Assumptions!$B$7 + Assumptions!$B$8 -> 220000 | H4: =F4 - G4 -> 50000 | I4: =H4 / Assumptions!$B$10 -> 0.025 | J4: =IF(B4>150,"Strongly Recommended",IF(B4>120,"Worth Considering",IF(B4>100,"Low Potential","Strongly Discouraged"))) -> Strongly Recommended | K4: =G4 / Assumptions!$B$9 -> 880000 | L4: =K4 / (Assumptions!$B$2 * Assumptions!$B$4) -> 65.185185 | M4: =IF(H4 > 0, "Profitable", "Needs Improvement") -> Profitable
A5: =INDEX(MumbaiLocationAnalysis[], ROW()-1, 1) -> Marine Lines | B5: =INDEX(MumbaiLocationAnalysis[], ROW()-1, MATCH("restaurant", MumbaiLocationAnalysis[#Headers], 0))*0.8 + INDEX(MumbaiLocationAnalysis[], ROW()-1, MATCH("shopping_mall", MumbaiLocationAnalysis[#Headers], 0))*0.7 + INDEX(MumbaiLocationAnalysis[], ROW()-1, MATCH("office", MumbaiLocationAnalysis[#Headers], 0))*0.6 + INDEX(MumbaiLocationAnalysis[], ROW()-1, MATCH("park", MumbaiLocationAnalysis[#Headers], 0))*0.5 + INDEX(MumbaiLocationAnalysis[], ROW()-1, MATCH("gym", MumbaiLocationAnalysis[#Headers], 0))*0.4 + INDEX(MumbaiLocationAnalysis[], ROW()-1, MATCH("tourist_attraction", MumbaiLocationAnalysis[#Headers], 0))*0.6 + INDEX(MumbaiLocationAnalysis[], ROW()-1, MATCH("bank", MumbaiLocationAnalysis[#Headers], 0))*0.3 + INDEX(MumbaiLocationAnalysis[], ROW()-1, MATCH("hospital", MumbaiLocationAnalysis[#Headers], 0))*0.3 + INDEX(MumbaiLocationAnalysis[], ROW()-1, MATCH("school", MumbaiLocationAnalysis[#Headers], 0))*0.3 - INDEX(MumbaiLocationAnalysis[], ROW()-1, MATCH("cafe", MumbaiLocationAnalysis[#Headers], 0))*0.8 -> 33.3 | C5: =INDEX(MumbaiLocationAnalysis[], ROW()-1, MATCH("restaurant", MumbaiLocationAnalysis[#Headers], 0)) + INDEX(MumbaiLocationAnalysis[], ROW()-1, MATCH("shopping_mall", MumbaiLocationAnalysis[#Headers], 0)) + INDEX(MumbaiLocationAnalysis[], ROW()-1, MATCH("office", MumbaiLocationAnalysis[#Headers], 0)) + INDEX(MumbaiLocationAnalysis[], ROW()-1, MATCH("park", MumbaiLocationAnalysis[#Headers], 0)) + INDEX(MumbaiLocationAnalysis[], ROW()-1, MATCH("tourist_attraction", MumbaiLocationAnalysis[#Headers], 0)) -> 45 | D5: =INDEX(MumbaiLocationAnalysis[], ROW()-1, MATCH("cafe", MumbaiLocationAnalysis[#Headers], 0)) -> 9 | E5: =(C5 * Assumptions!$B$3 / 1000) * Assumptions!$B$15 -> 3.6 | F5: =E5 * Assumptions!$B$2 * Assumptions!$B$4 -> 48600 | G5: =(Assumptions!$B$5 * Assumptions!$B$13) + Assumptions!$B$6 + Assumptions!$B$7 + Assumptions!$B$8 -> 220000 | H5: =F5 - G5 -> -171400 | I5: =H5 / Assumptions!$B$10 -> -0.0857 | J5: =IF(B5>150,"Strongly Recommended",IF(B5>120,"Worth Considering",IF(B5>100,"Low Potential","Strongly Discouraged"))) -> Strongly Discouraged | K5: =G5 / Assumptions!$B$9 -> 880000 | L5: =K5 / (Assumptions!$B$2 * Assumptions!$B$4) -> 65.185185 | M5: =IF(H5 > 0, "Profitable", "Needs Improvement") -> Needs Improvement
A6: =INDEX(MumbaiLocationAnalysis[], ROW()-1, 1) -> Dadar | B6: =INDEX(MumbaiLocationAnalysis[], ROW()-1, MATCH("restaurant", MumbaiLocationAnalysis[#Headers], 0))*0.8 + INDEX(MumbaiLocationAnalysis[], ROW()-1, MATCH("shopping_mall", MumbaiLocationAnalysis[#Headers], 0))*0.7 + INDEX(MumbaiLocationAnalysis[], ROW()-1, MATCH("office", MumbaiLocationAnalysis[#Headers], 0))*0.6 + INDEX(MumbaiLocationAnalysis[], ROW()-1, MATCH("park", MumbaiLocationAnalysis[#Headers], 0))*0.5 + INDEX(MumbaiLocationAnalysis[], ROW()-1, MATCH("gym", MumbaiLocationAnalysis[#Headers], 0))*0.4 + INDEX(MumbaiLocationAnalysis[], ROW()-1, MATCH("tourist_attraction", MumbaiLocationAnalysis[#Headers], 0))*0.6 + INDEX(MumbaiLocationAnalysis[], ROW()-1, MATCH("bank", MumbaiLocationAnalysis[#Headers], 0))*0.3 + INDEX(MumbaiLocationAnalysis[], ROW()-1, MATCH("hospital", MumbaiLocationAnalysis[#Headers], 0))*0.3 + INDEX(MumbaiLocationAnalysis[], ROW()-1, MATCH("school", MumbaiLocationAnalysis[#Headers], 0))*0.3 - INDEX(MumbaiLocationAnalysis[], ROW()-1, MATCH("cafe", MumbaiLocationAnalysis[#Headers], 0))*0.8 -> 81.4 | C6: =INDEX(MumbaiLocationAnalysis[], ROW()-1, MATCH("restaurant", MumbaiLocationAnalysis[#Headers], 0)) + INDEX(MumbaiLocationAnalysis[], ROW()-1, MATCH("shopping_mall", MumbaiLocationAnalysis[#Headers], 0)) + INDEX(MumbaiLocationAnalysis[], ROW()-1, MATCH("office", MumbaiLocationAnalysis[#Headers], 0)) + INDEX(MumbaiLocationAnalysis[], ROW()-1, MATCH("park", MumbaiLocationAnalysis[#Headers], 0)) + INDEX(MumbaiLocationAnalysis[], ROW()-1, MATCH("tourist_attraction", MumbaiLocationAnalysis[#Headers], 0)) -> 110 | D6: =INDEX(MumbaiLocationAnalysis[], ROW()-1, MATCH("cafe", MumbaiLocationAnalysis[#Headers], 0)) -> 22 | E6: =(C6 * Assumptions!$B$3 / 1000) * Assumptions!$B$15 -> 8.8 | F6: =E6 * Assumptions!$B$2 * Assumptions!$B$4 -> 118800 | G6: =(Assumptions!$B$5 * Assumptions!$B$13) + Assumptions!$B$6 + Assumptions!$B$7 + Assumptions!$B$8 -> 220000 | H6: =F6 - G6 -> -101200 | I6: =H6 / Assumptions!$B$10 -> -0.0506 | J6: =IF(B6>150,"Strongly Recommended",IF(B6>120,"Worth Considering",IF(B6>100,"Low Potential","Strongly Discouraged"))) -> Strongly Discouraged | K6: =G6 / Assumptions!$B$9 -> 880000 | L6: =K6 / (Assumptions!$B$2 * Assumptions!$B$4) -> 65.185185 | M6: =IF(H6 > 0, "Profitable", "Needs Improvement") -> Needs Improvement
A7: =INDEX(MumbaiLocationAnalysis[], ROW()-1, 1) -> Lower Parel | B7: =INDEX(MumbaiLocationAnalysis[], ROW()-1, MATCH("restaurant", MumbaiLocationAnalysis[#Headers], 0))*0.8 + INDEX(MumbaiLocationAnalysis[], ROW()-1, MATCH("shopping_mall", MumbaiLocationAnalysis[#Headers], 0))*0.7 + INDEX(MumbaiLocationAnalysis[], ROW()-1, MATCH("office", MumbaiLocationAnalysis[#Headers], 0))*0.6 + INDEX(MumbaiLocationAnalysis[], ROW()-1, MATCH("park", MumbaiLocationAnalysis[#Headers], 0))*0.5 + INDEX(MumbaiLocationAnalysis[], ROW()-1, MATCH("gym", MumbaiLocationAnalysis[#Headers], 0))*0.4 + INDEX(MumbaiLocationAnalysis[], ROW()-1, MATCH("tourist_attraction", MumbaiLocationAnalysis[#Headers], 0))*0.6 + INDEX(MumbaiLocationAnalysis[], ROW()-1, MATCH("bank", MumbaiLocationAnalysis[#Headers], 0))*0.3 + INDEX(MumbaiLocationAnalysis[], ROW()-1, MATCH("hospital", MumbaiLocationAnalysis[#Headers], 0))*0.3 + INDEX(MumbaiLocationAnalysis[], ROW()-1, MATCH("school", MumbaiLocationAnalysis[#Headers], 0))*0.3 - INDEX(MumbaiLocationAnalysis[], ROW()-1, MATCH("cafe", MumbaiLocationAnalysis[#Headers], 0))*0.8 -> 185 | C7: =INDEX(MumbaiLocationAnalysis[], ROW()-1, MATCH("restaurant", MumbaiLocationAnalysis[#Headers], 0)) + INDEX(MumbaiLocationAnalysis[], ROW()-1, MATCH("shopping_mall", MumbaiLocationAnalysis[#Headers], 0)) + INDEX(MumbaiLocationAnalysis[], ROW()-1, MATCH("office", MumbaiLocationAnalysis[#Headers], 0)) + INDEX(MumbaiLocationAnalysis[], ROW()-1, MATCH("park", MumbaiLocationAnalysis[#Headers], 0)) + INDEX(MumbaiLocationAnalysis[], ROW()-1, MATCH("tourist_attraction", MumbaiLocationAnalysis[#Headers], 0)) -> 250 | D7: =INDEX(MumbaiLocationAnalysis[], ROW()-1, MATCH("cafe", MumbaiLocationAnalysis[#Headers], 0)) -> 50 | E7: =(C7 * Assumptions!$B$3 / 1000) * Assumptions!$B$15 -> 20 | F7: =E7 * Assumptions!$B$2 * Assumptions!$B$4 -> 270000 | G7: =(Assumptions!$B$5 * Assumptions!$B$13) + Assumptions!$B$6 + Assumptions!$B$7 + Assumptions!$B$8 -> 220000 | H7: =F7 - G7 -> 50000 | I7: =H7 / Assumptions!$B$10 -> 0.025 | J7: =IF(B7>150,"Strongly Recommended",IF(B7>120,"Worth Considering",IF(B7>100,"Low Potential","Strongly Discouraged"))) -> Strongly Recommended | K7: =G7 / Assumptions!$B$9 -> 880000 | L7: =K7 / (Assumptions!$B$2 * Assumptions!$B$4) -> 65.185185 | M7: =IF(H7 > 0, "Profitable", "Needs Improvement") -> Profitable
A8: =INDEX(MumbaiLocationAnalysis[], ROW()-1, 1) -> Bandra West | B8: =INDEX(MumbaiLocationAnalysis[], ROW()-1, MATCH("restaurant", MumbaiLocationAnalysis[#Headers], 0))*0.8 + INDEX(MumbaiLocationAnalysis[], ROW()-1, MATCH("shopping_mall", MumbaiLocationAnalysis[#Headers], 0))*0.7 + INDEX(MumbaiLocationAnalysis[], ROW()-1, MATCH("office", MumbaiLocationAnalysis[#Headers], 0))*0.6 + INDEX(MumbaiLocationAnalysis[], ROW()-1, MATCH("park", MumbaiLocationAnalysis[#Headers], 0))*0.5 + INDEX(MumbaiLocationAnalysis[], ROW()-1, MATCH("gym", MumbaiLocationAnalysis[#Headers], 0))*0.4 + INDEX(MumbaiLocationAnalysis[], ROW()-1, MATCH("tourist_attraction", MumbaiLocationAnalysis[#Headers], 0))*0.6 + INDEX(MumbaiLocationAnalysis[], ROW()-1, MATCH("bank", MumbaiLocationAnalysis[#Headers], 0))*0.3 + INDEX(MumbaiLocationAnalysis[], ROW()-1, MATCH("hospital", MumbaiLocationAnalysis[#Headers], 0))*0.3 + INDEX(MumbaiLocationAnalysis[], ROW()-1, MATCH("school", MumbaiLocationAnalysis[#Headers], 0))*0.3 - INDEX(MumbaiLocationAnalysis[], ROW()-1, MATCH("cafe", MumbaiLocationAnalysis[#Headers], 0))*0.8 -> 185 | C8: =INDEX(MumbaiLocationAnalysis[], ROW()-1, MATCH("restaurant", MumbaiLocationAnalysis[#Headers], 0)) + INDEX(MumbaiLocationAnalysis[], ROW()-1, MATCH("shopping_mall", MumbaiLocationAnalysis[#Headers], 0)) + INDEX(MumbaiLocationAnalysis[], ROW()-1, MATCH("office", MumbaiLocationAnalysis[#Headers], 0)) + INDEX(MumbaiLocationAnalysis[], ROW()-1, MATCH("park", MumbaiLocationAnalysis[#Headers], 0)) + INDEX(MumbaiLocationAnalysis[], ROW()-1, MATCH("tourist_attraction", MumbaiLocationAnalysis[#Headers], 0)) -> 250 | D8: =INDEX(MumbaiLocationAnalysis[], ROW()-1, MATCH("cafe", MumbaiLocationAnalysis[#Headers], 0)) -> 50 | E8: =(C8 * Assumptions!$B$3 / 1000) * Assumptions!$B$15 -> 20 | F8: =E8 * Assumptions!$B$2 * Assumptions!$B$4 -> 270000 | G8: =(Assumptions!$B$5 * Assumptions!$B$13) + Assumptions!$B$6 + Assumptions!$B$7 + Assumptions!$B$8 -> 220000 | H8: =F8 - G8 -> 50000 | I8: =H8 / Assumptions!$B$10 -> 0.025 | J8: =IF(B8>150,"Strongly Recommended",IF(B8>120,"Worth Considering",IF(B8>100,"Low Potential","Strongly Discouraged"))) -> Strongly Recommended | K8: =G8 / Assumptions!$B$9 -> 880000 | L8: =K8 / (Assumptions!$B$2 * Assumptions!$B$4) -> 65.185185 | M8: =IF(H8 > 0, "Profitable", "Needs Improvement") -> Profitable
A9: =INDEX(MumbaiLocationAnalysis[], ROW()-1, 1) -> Bandra Kurla Complex | B9: =INDEX(MumbaiLocationAnalysis[], ROW()-1, MATCH("restaurant", MumbaiLocationAnalysis[#Headers], 0))*0.8 + INDEX(MumbaiLocationAnalysis[], ROW()-1, MATCH("shopping_mall", MumbaiLocationAnalysis[#Headers], 0))*0.7 + INDEX(MumbaiLocationAnalysis[], ROW()-1, MATCH("office", MumbaiLocationAnalysis[#Headers], 0))*0.6 + INDEX(MumbaiLocationAnalysis[], ROW()-1, MATCH("park", MumbaiLocationAnalysis[#Headers], 0))*0.5 + INDEX(MumbaiLocationAnalysis[], ROW()-1, MATCH("gym", MumbaiLocationAnalysis[#Headers], 0))*0.4 + INDEX(MumbaiLocationAnalysis[], ROW()-1, MATCH("tourist_attraction", MumbaiLocationAnalysis[#Headers], 0))*0.6 + INDEX(MumbaiLocationAnalysis[], ROW()-1, MATCH("bank", MumbaiLocationAnalysis[#Headers], 0))*0.3 + INDEX(MumbaiLocationAnalysis[], ROW()-1, MATCH("hospital", MumbaiLocationAnalysis[#Headers], 0))*0.3 + INDEX(MumbaiLocationAnalysis[], ROW()-1, MATCH("school", MumbaiLocationAnalysis[#Headers], 0))*0.3 - INDEX(MumbaiLocationAnalysis[], ROW()-1, MATCH("cafe", MumbaiLocationAnalysis[#Headers], 0))*0.8 -> 107.3 | C9: =INDEX(MumbaiLocationAnalysis[], ROW()-1, MATCH("restaurant", MumbaiLocationAnalysis[#Headers], 0)) + INDEX(MumbaiLocationAnalysis[], ROW()-1, MATCH("shopping_mall", MumbaiLocationAnalysis[#Headers], 0)) + INDEX(MumbaiLocationAnalysis[], ROW()-1, MATCH("office", MumbaiLocationAnalysis[#Headers], 0)) + INDEX(MumbaiLocationAnalysis[], ROW()-1, MATCH("park", MumbaiLocationAnalysis[#Headers], 0)) + INDEX(MumbaiLocationAnalysis[], ROW()-1, MATCH("tourist_attraction", MumbaiLocationAnalysis[#Headers], 0)) -> 145 | D9: =INDEX(MumbaiLocationAnalysis[], ROW()-1, MATCH("cafe", MumbaiLocationAnalysis[#Headers], 0)) -> 29 | E9: =(C9 * Assumptions!$B$3 / 1000) * Assumptions!$B$15 -> 11.6 | F9: =E9 * Assumptions!$B$2 * Assumptions!$B$4 -> 156600 | G9: =(Assumptions!$B$5 * Assumptions!$B$13) + Assumptions!$B$6 + Assumptions!$B$7 + Assumptions!$B$8 -> 220000 | H9: =F9 - G9 -> -63400 | I9: =H9 / Assumptions!$B$10 -> -0.0317 | J9: =IF(B9>150,"Strongly Recommended",IF(B9>120,"Worth Considering",IF(B9>100,"Low Potential","Strongly Discouraged"))) -> Low Potential | K9: =G9 / Assumptions!$B$9 -> 880000 | L9: =K9 / (Assumptions!$B$2 * Assumptions!$B$4) -> 65.185185 | M9: =IF(H9 > 0, "Profitable", "Needs Improvement") -> Needs Improvement
A10: =INDEX(MumbaiLocationAnalysis[], ROW()-1, 1) -> Andheri East | B10: =INDEX(MumbaiLocationAnalysis[], ROW()-1, MATCH("restaurant", MumbaiLocationAnalysis[#Headers], 0))*0.8 + INDEX(MumbaiLocationAnalysis[], ROW()-1, MATCH("shopping_mall", MumbaiLocationAnalysis[#Headers], 0))*0.7 + INDEX(MumbaiLocationAnalysis[], ROW()-1, MATCH("office", MumbaiLocationAnalysis[#Headers], 0))*0.6 + INDEX(MumbaiLocationAnalysis[], ROW()-1, MATCH("park", MumbaiLocationAnalysis[#Headers], 0))*0.5 + INDEX(MumbaiLocationAnalysis[], ROW()-1, MATCH("gym", MumbaiLocationAnalysis[#Headers], 0))*0.4 + INDEX(MumbaiLocationAnalysis[], ROW()-1, MATCH("tourist_attraction", MumbaiLocationAnalysis[#Headers], 0))*0.6 + INDEX(MumbaiLocationAnalysis[], ROW()-1, MATCH("bank", MumbaiLocationAnalysis[#Headers], 0))*0.3 + INDEX(MumbaiLocationAnalysis[], ROW()-1, MATCH("hospital", MumbaiLocationAnalysis[#Headers], 0))*0.3 + INDEX(MumbaiLocationAnalysis[], ROW()-1, MATCH("school", MumbaiLocationAnalysis[#Headers], 0))*0.3 - INDEX(MumbaiLocationAnalysis[], ROW()-1, MATCH("cafe", MumbaiLocationAnalysis[#Headers], 0))*0.8 -> 148 | C10: =INDEX(MumbaiLocationAnalysis[], ROW()-1, MATCH("restaurant", MumbaiLocationAnalysis[#Headers], 0)) + INDEX(MumbaiLocationAnalysis[], ROW()-1, MATCH("shopping_mall", MumbaiLocationAnalysis[#Headers], 0)) + INDEX(MumbaiLocationAnalysis[], ROW()-1, MATCH("office", MumbaiLocationAnalysis[#Headers], 0)) + INDEX(MumbaiLocationAnalysis[], ROW()-1, MATCH("park", MumbaiLocationAnalysis[#Headers], 0)) + INDEX(MumbaiLocationAnalysis[], ROW()-1, MATCH("tourist_attraction", MumbaiLocationAnalysis[#Headers], 0)) -> 200 | D10: =INDEX(MumbaiLocationAnalysis[], ROW()-1, MATCH("cafe", MumbaiLocationAnalysis[#Headers], 0)) -> 40 | E10: =(C10 * Assumptions!$B$3 / 1000) * Assumptions!$B$15 -> 16 | F10: =E10 * Assumptions!$B$2 * Assumptions!$B$4 -> 216000 | G10: =(Assumptions!$B$5 * Assumptions!$B$13) + Assumptions!$B$6 + Assumptions!$B$7 + Assumptions!$B$8 -> 220000 | H10: =F10 - G10 -> -4000 | I10: =H10 / Assumptions!$B$10 -> -0.002 | J10: =IF(B10>150,"Strongly Recommended",IF(B10>120,"Worth Considering",IF(B10>100,"Low Potential","Strongly Discouraged"))) -> Worth Considering | K10: =G10 / Assumptions!$B$9 -> 880000 | L10: =K10 / (Assumptions!$B$2 * Assumptions!$B$4) -> 65.185185 | M10: =IF(H10 > 0, "Profitable", "Needs Improvement") -> Needs Improvement
A11: =INDEX(MumbaiLocationAnalysis[], ROW()-1, 1) -> Andheri West | B11: =INDEX(MumbaiLocationAnalysis[], ROW()-1, MATCH("restaurant", MumbaiLocationAnalysis[#Headers], 0))*0.8 + INDEX(MumbaiLocationAnalysis[], ROW()-1, MATCH("shopping_mall", MumbaiLocationAnalysis[#Headers], 0))*0.7 + INDEX(MumbaiLocationAnalysis[], ROW()-1, MATCH("office", MumbaiLocationAnalysis[#Headers], 0))*0.6 + INDEX(MumbaiLocationAnalysis[], ROW()-1, MATCH("park", MumbaiLocationAnalysis[#Headers], 0))*0.5 + INDEX(MumbaiLocationAnalysis[], ROW()-1, MATCH("gym", MumbaiLocationAnalysis[#Headers], 0))*0.4 + INDEX(MumbaiLocationAnalysis[], ROW()-1, MATCH("tourist_attraction", MumbaiLocationAnalysis[#Headers], 0))*0.6 + INDEX(MumbaiLocationAnalysis[], ROW()-1, MATCH("bank", MumbaiLocationAnalysis[#Headers], 0))*0.3 + INDEX(MumbaiLocationAnalysis[], ROW()-1, MATCH("hospital", MumbaiLocationAnalysis[#Headers], 0))*0.3 + INDEX(MumbaiLocationAnalysis[], ROW()-1, MATCH("school", MumbaiLocationAnalysis[#Headers], 0))*0.3 - INDEX(MumbaiLocationAnalysis[], ROW()-1, MATCH("cafe", MumbaiLocationAnalysis[#Headers], 0))*0.8 -> 48.1 | C11: =INDEX(MumbaiLocationAnalysis[], ROW()-1, MATCH("restaurant", MumbaiLocationAnalysis[#Headers], 0)) + INDEX(MumbaiLocationAnalysis[], ROW()-1, MATCH("shopping_mall", MumbaiLocationAnalysis[#Headers], 0)) + INDEX(MumbaiLocationAnalysis[], ROW()-1, MATCH("office", MumbaiLocationAnalysis[#Headers], 0)) + INDEX(MumbaiLocationAnalysis[], ROW()-1, MATCH("park", MumbaiLocationAnalysis[#Headers], 0)) + INDEX(MumbaiLocationAnalysis[], ROW()-1, MATCH("tourist_attraction", MumbaiLocationAnalysis[#Headers], 0)) -> 65 | D11: =INDEX(MumbaiLocationAnalysis[], ROW()-1, MATCH("cafe", MumbaiLocationAnalysis[#Headers], 0)) -> 13 | E11: =(C11 * Assumptions!$B$3 / 1000) * Assumptions!$B$15 -> 5.2 | F11: =E11 * Assumptions!$B$2 * Assumptions!$B$4 -> 70200 | G11: =(Assumptions!$B$5 * Assumptions!$B$13) + Assumptions!$B$6 + Assumptions!$B$7 + Assumptions!$B$8 -> 220000 | H11: =F11 - G11 -> -149800 | I11: =H11 / Assumptions!$B$10 -> -0.0749 | J11: =IF(B11>150,"Strongly Recommended",IF(B11>120,"Worth Considering",IF(B11>100,"Low Potential","Strongly Discouraged"))) -> Strongly Discouraged | K11: =G11 / Assumptions!$B$9 -> 880000 | L11: =K11 / (Assumptions!$B$2 * Assumptions!$B$4) -> 65.185185 | M11: =IF(H11 > 0, "Profitable", "Needs Improvement") -> Needs Improvement
A12: =INDEX(MumbaiLocationAnalysis[], ROW()-1, 1) -> Juhu | B12: =INDEX(MumbaiLocationAnalysis[], ROW()-1, MATCH("restaurant", MumbaiLocationAnalysis[#Headers], 0))*0.8 + INDEX(MumbaiLocationAnalysis[], ROW()-1, MATCH("shopping_mall", MumbaiLocationAnalysis[#Headers], 0))*0.7 + INDEX(MumbaiLocationAnalysis[], ROW()-1, MATCH("office", MumbaiLocationAnalysis[#Headers], 0))*0.6 + INDEX(MumbaiLocationAnalysis[], ROW()-1, MATCH("park", MumbaiLocationAnalysis[#Headers], 0))*0.5 + INDEX(MumbaiLocationAnalysis[], ROW()-1, MATCH("gym", MumbaiLocationAnalysis[#Headers], 0))*0.4 + INDEX(MumbaiLocationAnalysis[], ROW()-1, MATCH("tourist_attraction", MumbaiLocationAnalysis[#Headers], 0))*0.6 + INDEX(MumbaiLocationAnalysis[], ROW()-1, MATCH("bank", MumbaiLocationAnalysis[#Headers], 0))*0.3 + INDEX(MumbaiLocationAnalysis[], ROW()-1, MATCH("hospital", MumbaiLocationAnalysis[#Headers], 0))*0.3 + INDEX(MumbaiLocationAnalysis[], ROW()-1, MATCH("school", MumbaiLocationAnalysis[#Headers], 0))*0.3 - INDEX(MumbaiLocationAnalysis[], ROW()-1, MATCH("cafe", MumbaiLocationAnalysis[#Headers], 0))*0.8 -> 185 | C12: =INDEX(MumbaiLocationAnalysis[], ROW()-1, MATCH("restaurant", MumbaiLocationAnalysis[#Headers], 0)) + INDEX(MumbaiLocationAnalysis[], ROW()-1, MATCH("shopping_mall", MumbaiLocationAnalysis[#Headers], 0)) + INDEX(MumbaiLocationAnalysis[], ROW()-1, MATCH("office", MumbaiLocationAnalysis[#Headers], 0)) + INDEX(MumbaiLocationAnalysis[], ROW()-1, MATCH("park", MumbaiLocationAnalysis[#Headers], 0)) + INDEX(MumbaiLocationAnalysis[], ROW()-1, MATCH("tourist_attraction", MumbaiLocationAnalysis[#Headers], 0)) -> 250 | D12: =INDEX(MumbaiLocationAnalysis[], ROW()-1, MATCH("cafe", MumbaiLocationAnalysis[#Headers], 0)) -> 50 | E12: =(C12 * Assumptions!$B$3 / 1000) * Assumptions!$B$15 -> 20 | F12: =E12 * Assumptions!$B$2 * Assumptions!$B$4 -> 270000 | G12: =(Assumptions!$B$5 * Assumptions!$B$13) + Assumptions!$B$6 + Assumptions!$B$7 + Assumptions!$B$8 -> 220000 | H12: =F12 - G12 -> 50000 | I12: =H12 / Assumptions!$B$10 -> 0.025 | J12: =IF(B12>150,"Strongly Recommended",IF(B12>120,"Worth Considering",IF(B12>100,"Low Potential","Strongly Discouraged"))) -> Strongly Recommended | K12: =G12 / Assumptions!$B$9 -> 880000 | L12: =K12 / (Assumptions!$B$2 * Assumptions!$B$4) -> 65.185185 | M12: =IF(H12 > 0, "Profitable", "Needs Improvement") -> Profitable
A13: =INDEX(MumbaiLocationAnalysis[], ROW()-1, 1) -> Powai | B13: =INDEX(MumbaiLocationAnalysis[], ROW()-1, MATCH("restaurant", MumbaiLocationAnalysis[#Headers], 0))*0.8 + INDEX(MumbaiLocationAnalysis[], ROW()-1, MATCH("shopping_mall", MumbaiLocationAnalysis[#Headers], 0))*0.7 + INDEX(MumbaiLocationAnalysis[], ROW()-1, MATCH("office", MumbaiLocationAnalysis[#Headers], 0))*0.6 + INDEX(MumbaiLocationAnalysis[], ROW()-1, MATCH("park", MumbaiLocationAnalysis[#Headers], 0))*0.5 + INDEX(MumbaiLocationAnalysis[], ROW()-1, MATCH("gym", MumbaiLocationAnalysis[#Headers], 0))*0.4 + INDEX(MumbaiLocationAnalysis[], ROW()-1, MATCH("tourist_attraction", MumbaiLocationAnalysis[#Headers], 0))*0.6 + INDEX(MumbaiLocationAnalysis[], ROW()-1, MATCH("bank", MumbaiLocationAnalysis[#Headers], 0))*0.3 + INDEX(MumbaiLocationAnalysis[], ROW()-1, MATCH("hospital", MumbaiLocationAnalysis[#Headers], 0))*0.3 + INDEX(MumbaiLocationAnalysis[], ROW()-1, MATCH("school", MumbaiLocationAnalysis[#Headers], 0))*0.3 - INDEX(MumbaiLocationAnalysis[], ROW()-1, MATCH("cafe", MumbaiLocationAnalysis[#Headers], 0))*0.8 -> 122.1 | C13: =INDEX(MumbaiLocationAnalysis[], ROW()-1, MATCH("restaurant", MumbaiLocationAnalysis[#Headers], 0)) + INDEX(MumbaiLocationAnalysis[], ROW()-1, MATCH("shopping_mall", MumbaiLocationAnalysis[#Headers], 0)) + INDEX(MumbaiLocationAnalysis[], ROW()-1, MATCH("office", MumbaiLocationAnalysis[#Headers], 0)) + INDEX(MumbaiLocationAnalysis[], ROW()-1, MATCH("park", MumbaiLocationAnalysis[#Headers], 0)) + INDEX(MumbaiLocationAnalysis[], ROW()-1, MATCH("tourist_attraction", MumbaiLocationAnalysis[#Headers], 0)) -> 165 | D13: =INDEX(MumbaiLocationAnalysis[], ROW()-1, MATCH("cafe", MumbaiLocationAnalysis[#Headers], 0)) -> 33 | E13: =(C13 * Assumptions!$B$3 / 1000) * Assumptions!$B$15 -> 13.2 | F13: =E13 * Assumptions!$B$2 * Assumptions!$B$4 -> 178200 | G13: =(Assumptions!$B$5 * Assumptions!$B$13) + Assumptions!$B$6 + Assumptions!$B$7 + Assumptions!$B$8 -> 220000 | H13: =F13 - G13 -> -41800 | I13: =H13 / Assumptions!$B$10 -> -0.0209 | J13: =IF(B13>150,"Strongly Recommended",IF(B13>120,"Worth Considering",IF(B13>100,"Low Potential","Strongly Discouraged"))) -> Worth Considering | K13: =G13 / Assumptions!$B$9 -> 880000 | L13: =K13 / (Assumptions!$B$2 * Assumptions!$B$4) -> 65.185185 | M13: =IF(H13 > 0, "Profitable", "Needs Improvement") -> Needs Improvement
... A22: =INDEX(MumbaiLocationAnalysis[], ROW()-1, 1) -> Vikhroli | B22: =INDEX(MumbaiLocationAnalysis[], ROW()-1, MATCH("restaurant", MumbaiLocationAnalysis[#Headers], 0))*0.8 + INDEX(MumbaiLocationAnalysis[], ROW()-1, MATCH("shopping_mall", MumbaiLocationAnalysis[#Headers], 0))*0.7 + INDEX(MumbaiLocationAnalysis[], ROW()-1, MATCH("office", MumbaiLocationAnalysis[#Headers], 0))*0.6 + INDEX(MumbaiLocationAnalysis[], ROW()-1, MATCH("park", MumbaiLocationAnalysis[#Headers], 0))*0.5 + INDEX(MumbaiLocationAnalysis[], ROW()-1, MATCH("gym", MumbaiLocationAnalysis[#Headers], 0))*0.4 + INDEX(MumbaiLocationAnalysis[], ROW()-1, MATCH("tourist_attraction", MumbaiLocationAnalysis[#Headers], 0))*0.6 + INDEX(MumbaiLocationAnalysis[], ROW()-1, MATCH("bank", MumbaiLocationAnalysis[#Headers], 0))*0.3 + INDEX(MumbaiLocationAnalysis[], ROW()-1, MATCH("hospital", MumbaiLocationAnalysis[#Headers], 0))*0.3 + INDEX(MumbaiLocationAnalysis[], ROW()-1, MATCH("school", MumbaiLocationAnalysis[#Headers], 0))*0.3 - INDEX(MumbaiLocationAnalysis[], ROW()-1, MATCH("cafe", MumbaiLocationAnalysis[#Headers], 0))*0.8 -> 14.8 | C22: =INDEX(MumbaiLocationAnalysis[], ROW()-1, MATCH("restaurant", MumbaiLocationAnalysis[#Headers], 0)) + INDEX(MumbaiLocationAnalysis[], ROW()-1, MATCH("shopping_mall", MumbaiLocationAnalysis[#Headers], 0)) + INDEX(MumbaiLocationAnalysis[], ROW()-1, MATCH("office", MumbaiLocationAnalysis[#Headers], 0)) + INDEX(MumbaiLocationAnalysis[], ROW()-1, MATCH("park", MumbaiLocationAnalysis[#Headers], 0)) + INDEX(MumbaiLocationAnalysis[], ROW()-1, MATCH("tourist_attraction", MumbaiLocationAnalysis[#Headers], 0)) -> 20 | D22: =INDEX(MumbaiLocationAnalysis[], ROW()-1, MATCH("cafe", MumbaiLocationAnalysis[#Headers], 0)) -> 4 | E22: =(C22 * Assumptions!$B$3 / 1000) * Assumptions!$B$15 -> 1.6 | F22: =E22 * Assumptions!$B$2 * Assumptions!$B$4 -> 21600 | G22: =(Assumptions!$B$5 * Assumptions!$B$13) + Assumptions!$B$6 + Assumptions!$B$7 + Assumptions!$B$8 -> 220000 | H22: =F22 - G22 -> -198400 | I22: =H22 / Assumptions!$B$10 -> -0.0992 | J22: =IF(B22>150,"Strongly Recommended",IF(B22>120,"Worth Considering",IF(B22>100,"Low Potential","Strongly Discouraged"))) -> Strongly Discouraged | K22: =G22 / Assumptions!$B$9 -> 880000 | L22: =K22 / (Assumptions!$B$2 * Assumptions!$B$4) -> 65.185185 | M22: =IF(H22 > 0, "Profitable", "Needs Improvement") -> Needs Improvement

Sheet Sensitivity
B1: Profit Scenario Matrix (Fort)
A2: Foot Traffic ↓ / Rent → | B2: 0.7 | C2: 0.8 | D2: 0.9 | E2: 1 | F2: 1.1 | G2: 1.2
A3: 0.6 | B3: =( (Model!$C$3 * Assumptions!$B$3 / 1000) * $A3 * Assumptions!$B$2 * Assumptions!$B$4 ) - ( (Assumptions!$B$5 * B$2) + Assumptions!$B$6 + Assumptions!$B$7 + Assumptions!$B$8 ) -> -31000 | C3: =( (Model!$C$3 * Assumptions!$B$3 / 1000) * $A3 * Assumptions!$B$2 * Assumptions!$B$4 ) - ( (Assumptions!$B$5 * C$2) + Assumptions!$B$6 + Assumptions!$B$7 + Assumptions!$B$8 ) -> -40000 | D3: =( (Model!$C$3 * Assumptions!$B$3 / 1000) * $A3 * Assumptions!$B$2 * Assumptions!$B$4 ) - ( (Assumptions!$B$5 * D$2) + Assumptions!$B$6 + Assumptions!$B$7 + Assumptions!$B$8 ) -> -49000 | E3: =( (Model!$C$3 * Assumptions!$B$3 / 1000) * $A3 * Assumptions!$B$2 * Assumptions!$B$4 ) - ( (Assumptions!$B$5 * E$2) + Assumptions!$B$6 + Assumptions!$B$7 + Assumptions!$B$8 ) -> -58000 | F3: =( (Model!$C$3 * Assumptions!$B$3 / 1000) * $A3 * Assumptions!$B$2 * Assumptions!$B$4 ) - ( (Assumptions!$B$5 * F$2) + Assumptions!$B$6 + Assumptions!$B$7 + Assumptions!$B$8 ) -> -67000 | G3: =( (Model!$C$3 * Assumptions!$B$3 / 1000) * $A3 * Assumptions!$B$2 * Assumptions!$B$4 ) - ( (Assumptions!$B$5 * G$2) + Assumptions!$B$6 + Assumptions!$B$7 + Assumptions!$B$8 ) -> -76000
A4: 0.8 | B4: =( (Model!$C$3 * Assumptions!$B$3 / 1000) * $A4 * Assumptions!$B$2 * Assumptions!$B$4 ) - ( (Assumptions!$B$5 * B$2) + Assumptions!$B$6 + Assumptions!$B$7 + Assumptions!$B$8 ) -> 23000 | C4: =( (Model!$C$3 * Assumptions!$B$3 / 1000) * $A4 * Assumptions!$B$2 * Assumptions!$B$4 ) - ( (Assumptions!$B$5 * C$2) + Assumptions!$B$6 + Assumptions!$B$7 + Assumptions!$B$8 ) -> 14000 | D4: =( (Model!$C$3 * Assumptions!$B$3 / 1000) * $A4 * Assumptions!$B$2 * Assumptions!$B$4 ) - ( (Assumptions!$B$5 * D$2) + Assumptions!$B$6 + Assumptions!$B$7 + Assumptions!$B$8 ) -> 5000 | E4: =( (Model!$C$3 * Assumptions!$B$3 / 1000) * $A4 * Assumptions!$B$2 * Assumptions!$B$4 ) - ( (Assumptions!$B$5 * E$2) + Assumptions!$B$6 + Assumptions!$B$7 + Assumptions!$B$8 ) -> -4000 | F4: =( (Model!$C$3 * Assumptions!$B$3 / 1000) * $A4 * Assumptions!$B$2 * Assumptions!$B$4 ) - ( (Assumptions!$B$5 * F$2) + Assumptions!$B$6 + Assumptions!$B$7 + Assumptions!$B$8 ) -> -13000 | G4: =( (Model!$C$3 * Assumptions!$B$3 / 1000) * $A4 * Assumptions!$B$2 * Assumptions!$B$4 ) - ( (Assumptions!$B$5 * G$2) + Assumptions!$B$6 + Assumptions!$B$7 + Assumptions!$B$8 ) -> -22000
A5: 1 | B5: =( (Model!$C$3 * Assumptions!$B$3 / 1000) * $A5 * Assumptions!$B$2 * Assumptions!$B$4 ) - ( (Assumptions!$B$5 * B$2) + Assumptions!$B$6 + Assumptions!$B$7 + Assumptions!$B$8 ) -> 77000 | C5: =( (Model!$C$3 * Assumptions!$B$3 / 1000) * $A5 * Assumptions!$B$2 * Assumptions!$B$4 ) - ( (Assumptions!$B$5 * C$2) + Assumptions!$B$6 + Assumptions!$B$7 + Assumptions!$B$8 ) -> 68000 | D5: =( (Model!$C$3 * Assumptions!$B$3 / 1000) * $A5 * Assumptions!$B$2 * Assumptions!$B$4 ) - ( (Assumptions!$B$5 * D$2) + Assumptions!$B$6 + Assumptions!$B$7 + Assumptions!$B$8 ) -> 59000 | E5: =( (Model!$C$3 * Assumptions!$B$3 / 1000) * $A5 * Assumptions!$B$2 * Assumptions!$B$4 ) - ( (Assumptions!$B$5 * E$2) + Assumptions!$B$6 + Assumptions!$B$7 + Assumptions!$B$8 ) -> 50000 | F5: =( (Model!$C$3 * Assumptions!$B$3 / 1000) * $A5 * Assumptions!$B$2 * Assumptions!$B$4 ) - ( (Assumptions!$B$5 * F$2) + Assumptions!$B$6 + Assumptions!$B$7 + Assumptions!$B$8 ) -> 41000 | G5: =( (Model!$C$3 * Assumptions!$B$3 / 1000) * $A5 * Assumptions!$B$2 * Assumptions!$B$4 ) - ( (Assumptions!$B$5 * G$2) + Assumptions!$B$6 + Assumptions!$B$7 + Assumptions!$B$8 ) -> 32000
A6: 1.2 | B6: =( (Model!$C$3 * Assumptions!$B$3 / 1000) * $A6 * Assumptions!$B$2 * Assumptions!$B$4 ) - ( (Assumptions!$B$5 * B$2) + Assumptions!$B$6 + Assumptions!$B$7 + Assumptions!$B$8 ) -> 131000 | C6: =( (Model!$C$3 * Assumptions!$B$3 / 1000) * $A6 * Assumptions!$B$2 * Assumptions!$B$4 ) - ( (Assumptions!$B$5 * C$2) + Assumptions!$B$6 + Assumptions!$B$7 + Assumptions!$B$8 ) -> 122000 | D6: =( (Model!$C$3 * Assumptions!$B$3 / 1000) * $A6 * Assumptions!$B$2 * Assumptions!$B$4 ) - ( (Assumptions!$B$5 * D$2) + Assumptions!$B$6 + Assumptions!$B$7 + Assumptions!$B$8 ) -> 113000 | E6: =( (Model!$C$3 * Assumptions!$B$3 / 1000) * $A6 * Assumptions!$B$2 * Assumptions!$B$4 ) - ( (Assumptions!$B$5 * E$2) + Assumptions!$B$6 + Assumptions!$B$7 + Assumptions!$B$8 ) -> 104000 | F6: =( (Model!$C$3 * Assumptions!$B$3 / 1000) * $A6 * Assumptions!$B$2 * Assumptions!$B$4 ) - ( (Assumptions!$B$5 * F$2) + Assumptions!$B$6 + Assumptions!$B$7 + Assumptions!$B$8 ) -> 95000 | G6: =( (Model!$C$3 * Assumptions!$B$3 / 1000) * $A6 * Assumptions!$B$2 * Assumptions!$B$4 ) - ( (Assumptions!$B$5 * G$2) + Assumptions!$B$6 + Assumptions!$B$7 + Assumptions!$B$8 ) -> 86000
A7: 1.4 | B7: =( (Model!$C$3 * Assumptions!$B$3 / 1000) * $A7 * Assumptions!$B$2 * Assumptions!$B$4 ) - ( (Assumptions!$B$5 * B$2) + Assumptions!$B$6 + Assumptions!$B$7 + Assumptions!$B$8 ) -> 185000 | C7: =( (Model!$C$3 * Assumptions!$B$3 / 1000) * $A7 * Assumptions!$B$2 * Assumptions!$B$4 ) - ( (Assumptions!$B$5 * C$2) + Assumptions!$B$6 + Assumptions!$B$7 + Assumptions!$B$8 ) -> 176000 | D7: =( (Model!$C$3 * Assumptions!$B$3 / 1000) * $A7 * Assumptions!$B$2 * Assumptions!$B$4 ) - ( (Assumptions!$B$5 * D$2) + Assumptions!$B$6 + Assumptions!$B$7 + Assumptions!$B$8 ) -> 167000 | E7: =( (Model!$C$3 * Assumptions!$B$3 / 1000) * $A7 * Assumptions!$B$2 * Assumptions!$B$4 ) - ( (Assumptions!$B$5 * E$2) + Assumptions!$B$6 + Assumptions!$B$7 + Assumptions!$B$8 ) -> 158000 | F7: =( (Model!$C$3 * Assumptions!$B$3 / 1000) * $A7 * Assumptions!$B$2 * Assumptions!$B$4 ) - ( (Assumptions!$B$5 * F$2) + Assumptions!$B$6 + Assumptions!$B$7 + Assumptions!$B$8 ) -> 149000 | G7: =( (Model!$C$3 * Assumptions!$B$3 / 1000) * $A7 * Assumptions!$B$2 * Assumptions!$B$4 ) - ( (Assumptions!$B$5 * G$2) + Assumptions!$B$6 + Assumptions!$B$7 + Assumptions!$B$8 ) -> 140000
